[2025-08-16T13:35:18.858+0000] {local_task_job_runner.py:120} INFO - ::group::Pre task execution logs
[2025-08-16T13:35:18.866+0000] {taskinstance.py:2076} INFO - Dependencies all met for dep_context=non-requeueable deps ti=<TaskInstance: generated_sql_select_data.execute_sql manual__2025-08-16T13:35:18.069405+00:00 [queued]>
[2025-08-16T13:35:18.868+0000] {taskinstance.py:2076} INFO - Dependencies all met for dep_context=requeueable deps ti=<TaskInstance: generated_sql_select_data.execute_sql manual__2025-08-16T13:35:18.069405+00:00 [queued]>
[2025-08-16T13:35:18.868+0000] {taskinstance.py:2306} INFO - Starting attempt 1 of 1
[2025-08-16T13:35:18.872+0000] {taskinstance.py:2330} INFO - Executing <Task(PythonOperator): execute_sql> on 2025-08-16 13:35:18.069405+00:00
[2025-08-16T13:35:18.874+0000] {warnings.py:112} WARNING - /home/***/.local/lib/python3.12/site-packages/***/task/task_runner/standard_task_runner.py:61: DeprecationWarning: This process (pid=60) is multi-threaded, use of fork() may lead to deadlocks in the child.
  pid = os.fork()

[2025-08-16T13:35:18.875+0000] {standard_task_runner.py:63} INFO - Started process 61 to run task
[2025-08-16T13:35:18.875+0000] {standard_task_runner.py:90} INFO - Running: ['***', 'tasks', 'run', 'generated_sql_select_data', 'execute_sql', 'manual__2025-08-16T13:35:18.069405+00:00', '--job-id', '36', '--raw', '--subdir', 'DAGS_FOLDER/generated_sql_select_data.py', '--cfg-path', '/tmp/tmpm00fw6p7']
[2025-08-16T13:35:18.875+0000] {standard_task_runner.py:91} INFO - Job 36: Subtask execute_sql
[2025-08-16T13:35:18.891+0000] {task_command.py:426} INFO - Running <TaskInstance: generated_sql_select_data.execute_sql manual__2025-08-16T13:35:18.069405+00:00 [running]> on host 1ed929767bb5
[2025-08-16T13:35:18.917+0000] {taskinstance.py:2648} INFO - Exporting env vars: AIRFLOW_CTX_DAG_OWNER='***' AIRFLOW_CTX_DAG_ID='generated_sql_select_data' AIRFLOW_CTX_TASK_ID='execute_sql' AIRFLOW_CTX_EXECUTION_DATE='2025-08-16T13:35:18.069405+00:00' AIRFLOW_CTX_TRY_NUMBER='1' AIRFLOW_CTX_DAG_RUN_ID='manual__2025-08-16T13:35:18.069405+00:00'
[2025-08-16T13:35:18.917+0000] {taskinstance.py:430} INFO - ::endgroup::
[2025-08-16T13:35:18.924+0000] {taskinstance.py:441} INFO - ::group::Post task execution logs
[2025-08-16T13:35:18.926+0000] {taskinstance.py:2905} ERROR - Task failed with exception
Traceback (most recent call last):
  File "/home/airflow/.local/lib/python3.12/site-packages/airflow/models/taskinstance.py", line 465, in _execute_task
    result = _execute_callable(context=context, **execute_callable_kwargs)
             ^^^^^^^^^^^^^^^^^^^^^^^^^^^^^^^^^^^^^^^^^^^^^^^^^^^^^^^^^^^^^
  File "/home/airflow/.local/lib/python3.12/site-packages/airflow/models/taskinstance.py", line 432, in _execute_callable
    return execute_callable(context=context, **execute_callable_kwargs)
           ^^^^^^^^^^^^^^^^^^^^^^^^^^^^^^^^^^^^^^^^^^^^^^^^^^^^^^^^^^^^
  File "/home/airflow/.local/lib/python3.12/site-packages/airflow/models/baseoperator.py", line 401, in wrapper
    return func(self, *args, **kwargs)
           ^^^^^^^^^^^^^^^^^^^^^^^^^^^
  File "/home/airflow/.local/lib/python3.12/site-packages/airflow/operators/python.py", line 235, in execute
    return_value = self.execute_callable()
                   ^^^^^^^^^^^^^^^^^^^^^^^
  File "/home/airflow/.local/lib/python3.12/site-packages/airflow/operators/python.py", line 252, in execute_callable
    return self.python_callable(*self.op_args, **self.op_kwargs)
           ^^^^^^^^^^^^^^^^^^^^^^^^^^^^^^^^^^^^^^^^^^^^^^^^^^^^^
  File "/opt/airflow/dags/generated_sql_select_data.py", line 12, in run_sql
    hook.run(sql)
  File "/home/airflow/.local/lib/python3.12/site-packages/airflow/providers/common/sql/hooks/sql.py", line 431, in run
    with self._create_autocommit_connection(autocommit) as conn:
  File "/usr/local/lib/python3.12/contextlib.py", line 137, in __enter__
    return next(self.gen)
           ^^^^^^^^^^^^^^
  File "/home/airflow/.local/lib/python3.12/site-packages/airflow/providers/common/sql/hooks/sql.py", line 551, in _create_autocommit_connection
    with closing(self.get_conn()) as conn:
                 ^^^^^^^^^^^^^^^
  File "/home/airflow/.local/lib/python3.12/site-packages/airflow/providers/postgres/hooks/postgres.py", line 145, in get_conn
    conn = deepcopy(self.connection or self.get_connection(conn_id))
                                       ^^^^^^^^^^^^^^^^^^^^^^^^^^^^
  File "/home/airflow/.local/lib/python3.12/site-packages/airflow/hooks/base.py", line 83, in get_connection
    conn = Connection.get_connection_from_secrets(conn_id)
           ^^^^^^^^^^^^^^^^^^^^^^^^^^^^^^^^^^^^^^^^^^^^^^^
  File "/home/airflow/.local/lib/python3.12/site-packages/airflow/models/connection.py", line 519, in get_connection_from_secrets
    raise AirflowNotFoundException(f"The conn_id `{conn_id}` isn't defined")
airflow.exceptions.AirflowNotFoundException: The conn_id `postgres_dfault` isn't defined
[2025-08-16T13:35:18.931+0000] {taskinstance.py:1206} INFO - Marking task as FAILED. dag_id=generated_sql_select_data, task_id=execute_sql, run_id=manual__2025-08-16T13:35:18.069405+00:00, execution_date=20250816T133518, start_date=20250816T133518, end_date=20250816T133518
[2025-08-16T13:35:18.936+0000] {standard_task_runner.py:110} ERROR - Failed to execute job 36 for task execute_sql (The conn_id `postgres_dfault` isn't defined; 61)
[2025-08-16T13:35:18.973+0000] {local_task_job_runner.py:240} INFO - Task exited with return code 1
[2025-08-16T13:35:18.979+0000] {taskinstance.py:3503} INFO - 0 downstream tasks scheduled from follow-on schedule check
[2025-08-16T13:35:18.979+0000] {local_task_job_runner.py:222} INFO - ::endgroup::
