[2025-09-04T12:17:47.537+0000] {scheduler_job_runner.py:769} ERROR - Executor reports task instance <TaskInstance: generated_py_do_something.f_task scheduled__2025-08-26T00:00:00+00:00 [queued]> finished (failed) although the task says it's queued. (Info: None) Was the task killed externally?
