[2025-08-13T21:15:03.453+0000] {local_task_job_runner.py:120} INFO - ::group::Pre task execution logs
[2025-08-13T21:15:03.462+0000] {taskinstance.py:2076} INFO - Dependencies all met for dep_context=non-requeueable deps ti=<TaskInstance: pg_extra_create_and_log.create_table manual__2025-08-13T21:15:02.629710+00:00 [queued]>
[2025-08-13T21:15:03.464+0000] {taskinstance.py:2076} INFO - Dependencies all met for dep_context=requeueable deps ti=<TaskInstance: pg_extra_create_and_log.create_table manual__2025-08-13T21:15:02.629710+00:00 [queued]>
[2025-08-13T21:15:03.464+0000] {taskinstance.py:2306} INFO - Starting attempt 1 of 1
[2025-08-13T21:15:03.468+0000] {taskinstance.py:2330} INFO - Executing <Task(PythonOperator): create_table> on 2025-08-13 21:15:02.629710+00:00
[2025-08-13T21:15:03.472+0000] {standard_task_runner.py:90} INFO - Running: ['***', 'tasks', 'run', 'pg_extra_create_and_log', 'create_table', 'manual__2025-08-13T21:15:02.629710+00:00', '--job-id', '14', '--raw', '--subdir', 'DAGS_FOLDER/main.py', '--cfg-path', '/tmp/tmp6qwqw4hz']
[2025-08-13T21:15:03.472+0000] {warnings.py:112} WARNING - /home/***/.local/lib/python3.12/site-packages/***/task/task_runner/standard_task_runner.py:61: DeprecationWarning: This process (pid=58) is multi-threaded, use of fork() may lead to deadlocks in the child.
  pid = os.fork()

[2025-08-13T21:15:03.473+0000] {standard_task_runner.py:91} INFO - Job 14: Subtask create_table
[2025-08-13T21:15:03.473+0000] {standard_task_runner.py:63} INFO - Started process 59 to run task
[2025-08-13T21:15:03.490+0000] {task_command.py:426} INFO - Running <TaskInstance: pg_extra_create_and_log.create_table manual__2025-08-13T21:15:02.629710+00:00 [running]> on host 1ed929767bb5
[2025-08-13T21:15:03.517+0000] {taskinstance.py:2648} INFO - Exporting env vars: AIRFLOW_CTX_DAG_OWNER='***' AIRFLOW_CTX_DAG_ID='pg_extra_create_and_log' AIRFLOW_CTX_TASK_ID='create_table' AIRFLOW_CTX_EXECUTION_DATE='2025-08-13T21:15:02.629710+00:00' AIRFLOW_CTX_TRY_NUMBER='1' AIRFLOW_CTX_DAG_RUN_ID='manual__2025-08-13T21:15:02.629710+00:00'
[2025-08-13T21:15:03.517+0000] {taskinstance.py:430} INFO - ::endgroup::
[2025-08-13T21:15:03.528+0000] {base.py:84} INFO - Using connection ID 'pg_extra_conn' for task execution.
[2025-08-13T21:15:03.530+0000] {taskinstance.py:441} INFO - ::group::Post task execution logs
[2025-08-13T21:15:03.531+0000] {taskinstance.py:2905} ERROR - Task failed with exception
Traceback (most recent call last):
  File "/home/airflow/.local/lib/python3.12/site-packages/airflow/models/taskinstance.py", line 465, in _execute_task
    result = _execute_callable(context=context, **execute_callable_kwargs)
             ^^^^^^^^^^^^^^^^^^^^^^^^^^^^^^^^^^^^^^^^^^^^^^^^^^^^^^^^^^^^^
  File "/home/airflow/.local/lib/python3.12/site-packages/airflow/models/taskinstance.py", line 432, in _execute_callable
    return execute_callable(context=context, **execute_callable_kwargs)
           ^^^^^^^^^^^^^^^^^^^^^^^^^^^^^^^^^^^^^^^^^^^^^^^^^^^^^^^^^^^^
  File "/home/airflow/.local/lib/python3.12/site-packages/airflow/models/baseoperator.py", line 401, in wrapper
    return func(self, *args, **kwargs)
           ^^^^^^^^^^^^^^^^^^^^^^^^^^^
  File "/home/airflow/.local/lib/python3.12/site-packages/airflow/operators/python.py", line 235, in execute
    return_value = self.execute_callable()
                   ^^^^^^^^^^^^^^^^^^^^^^^
  File "/home/airflow/.local/lib/python3.12/site-packages/airflow/operators/python.py", line 252, in execute_callable
    return self.python_callable(*self.op_args, **self.op_kwargs)
           ^^^^^^^^^^^^^^^^^^^^^^^^^^^^^^^^^^^^^^^^^^^^^^^^^^^^^
  File "/opt/airflow/dags/main.py", line 14, in create_table
    with hook.get_conn() as conn:
         ^^^^^^^^^^^^^^^
  File "/home/airflow/.local/lib/python3.12/site-packages/airflow/providers/postgres/hooks/postgres.py", line 175, in get_conn
    self.conn = psycopg2.connect(**conn_args)
                ^^^^^^^^^^^^^^^^^^^^^^^^^^^^^
  File "/home/airflow/.local/lib/python3.12/site-packages/psycopg2/__init__.py", line 122, in connect
    conn = _connect(dsn, connection_factory=connection_factory, **kwasync)
           ^^^^^^^^^^^^^^^^^^^^^^^^^^^^^^^^^^^^^^^^^^^^^^^^^^^^^^^^^^^^^^^
psycopg2.OperationalError: connection to server at "pg_extra" (172.23.0.4), port 5432 failed: fe_sendauth: no password supplied

[2025-08-13T21:15:03.535+0000] {taskinstance.py:1206} INFO - Marking task as FAILED. dag_id=pg_extra_create_and_log, task_id=create_table, run_id=manual__2025-08-13T21:15:02.629710+00:00, execution_date=20250813T211502, start_date=20250813T211503, end_date=20250813T211503
[2025-08-13T21:15:03.539+0000] {standard_task_runner.py:110} ERROR - Failed to execute job 14 for task create_table (connection to server at "pg_extra" (172.23.0.4), port 5432 failed: fe_sendauth: no password supplied
; 59)
[2025-08-13T21:15:03.575+0000] {local_task_job_runner.py:240} INFO - Task exited with return code 1
[2025-08-13T21:15:03.584+0000] {taskinstance.py:3503} INFO - 0 downstream tasks scheduled from follow-on schedule check
[2025-08-13T21:15:03.585+0000] {local_task_job_runner.py:222} INFO - ::endgroup::
